<?xml version="1.0" ?>
<sdf version="1.7">
  <model name="gpg3_gopi5go_dave">  
    <pose>0.0 0.0 0.0 0.0 0.0 0.0</pose>

    <!-- Allow either base_link or base_footprint -->
    <link name="base_footprint"/>
    <link name="base_link">

      <!-- Mass 2.5lbs 1.13kg and m*(dim/2)^2 in kg/m2 -->
      <inertial>
        <!-- REMEMBER 0,0,0 is at center of shape -->
        <pose>0 0 0.19 0 0 0</pose>
        <inertia>
          <ixx>0.018</ixx>
          <ixy>0.000</ixy>
          <ixz>0.000</ixz>
          <iyy>0.004</iyy>
          <iyz>0.000</iyz>
          <izz>0.041</izz>
        </inertia>
        <mass>1.13</mass>
      </inertial>

      <collision name="base_collision">
        <pose>0 0 0.046 0 0 0</pose>
        <geometry>
          <box>
            <size>0.23 0.14 0.09</size>
          </box>
        </geometry>
      </collision>

      <visual name="base_visual">
        <pose>-0.017 0 0.047 0 0 0</pose>
        <geometry>
            <box>
              <size>0.216 0.103 0.004</size>
            </box>
        </geometry>
        <!-- <material name="blue"/> -->
      </visual>

      <visual name="rear_plate_visual">
        <pose>-0.114 0 0.0225 0 0 0</pose>
        <geometry>
          <box>
            <size>0.025 0.055 0.002</size>
          </box>
        </geometry>
      </visual>

      <visual name="castor_standoff_left_visual">
        <pose>-0.114 -0.018 0.035 0 0 0</pose>
        <geometry>
          <cylinder>
            <length>0.025</length>
            <radius>0.004</radius>
          </cylinder>
        </geometry>
      </visual>

      <visual name="castor_standoff_right_visual">
        <pose>-0.114 0.018 0.035 0 0 0</pose>
        <geometry>
          <cylinder>
            <length>0.025</length>
            <radius>0.004</radius>
          </cylinder>
        </geometry>
      </visual>



      <visual name="level_2_visual">
        <pose>-0.017 0 0.096 0 0 0</pose>
        <geometry>
            <box>
              <size>0.216 0.103 0.004</size>
            </box>
        </geometry>
        <!-- <material name="blue"/> -->
      </visual>

      <visual name="level_3_visual">
        <pose>0 0 0.148 0 0 0</pose>
        <geometry>
            <box>
              <size>0.128 0.104 0.004</size>
            </box>
        </geometry>
        <!-- <material name="blue"/> -->
      </visual>

      <visual name="level_4_visual">
        <pose>0 0 0.223 0 0 0</pose>
        <geometry>
            <box>
              <size>0.128 0.104 0.004</size>
            </box>
        </geometry>
        <!-- <material name="blue"/> -->
      </visual>

      <visual name="dave_body_bottom_visual">
        <pose>-0.04 0 0.250 0 0 0</pose>
        <geometry>
            <cylinder>
              <length>0.045</length>
              <radius>0.0375</radius>
            </cylinder>
        </geometry>
        <material>
          <ambient>0.377 0.805 0.847 1</ambient>
          <diffuse>0.419 0.725 0.941 1</diffuse>
        </material>
      </visual>

      <visual name="dave_body_top_visual">
        <pose>-0.04 0 0.295 0 0 0</pose>
        <geometry>
            <cylinder>
              <length>0.045</length>
              <radius>0.0375</radius>
            </cylinder>
        </geometry>
        <material>
          <ambient>0.9 0.847 0 1</ambient>
          <diffuse>1 0.94 0 1</diffuse>
        </material>
      </visual>

      <visual name="dave_head_visual">
        <pose>-0.04 0 0.317 0 0 0</pose>
        <geometry>
            <sphere>
              <radius>0.0375</radius>
            </sphere>
        </geometry>
        <material>
          <ambient>0.9 0.847 0 1</ambient>
          <diffuse>1 0.94 0 1</diffuse>
        </material>
      </visual>

      <visual name="right_goggle_visual">
        <pose>0 -0.0075 0.317 0 1.57 0</pose>
        <geometry>
            <cylinder>
              <length>0.008</length>
              <radius>0.015</radius>
            </cylinder>
        </geometry>
        <!-- <material name="yellow" /> -->
      </visual>

      <visual name="left_goggle_visual">
        <pose>0 0.0075 0.317 0 1.57 0</pose>
        <geometry>
            <cylinder>
              <length>0.008</length>
              <radius>0.015</radius>
            </cylinder>
        </geometry>
      </visual>


      <visual name="right_eyeball_visual">
        <pose>0.0065 -0.0075 0.317 0 1.57 0</pose>
        <geometry>
            <cylinder>
              <length>0.001</length>
              <radius>0.012</radius>
            </cylinder>
        </geometry>
        <material>
          <ambient>0.9 0.9 0.9 1</ambient>
          <diffuse>1 1 1 1</diffuse>
        </material>
      </visual>

      <visual name="left_eyeball_visual">
        <pose>0.0065 0.0075 0.317 0 1.57 0</pose>
        <geometry>
            <cylinder>
              <length>0.001</length>
              <radius>0.012</radius>
            </cylinder>
        </geometry>
        <material>
          <ambient>0.9 0.9 0.9 1</ambient>
          <diffuse>1 1 1 1</diffuse>
        </material>
      </visual>

      <visual name="right_eye_visual">
        <pose>0.0068 -0.0075 0.317 0 1.57 0</pose>
        <geometry>
            <cylinder>
              <length>0.001</length>
              <radius>0.004</radius>
            </cylinder>
        </geometry>
        <material>
          <ambient>0.09 0.09 0.09 1</ambient>
          <diffuse>0.1 0.1 0.1 1</diffuse>
        </material>
      </visual>

      <visual name="left_eye_visual">
        <pose>0.0068 0.0075 0.317 0 1.57 0</pose>
        <geometry>
            <cylinder>
              <length>0.001</length>
              <radius>0.004</radius>
            </cylinder>
        </geometry>
        <material>
          <ambient>0.09 0.09 0.09 1</ambient>
          <diffuse>0.1 0.1 0.1 1</diffuse>
        </material>
      </visual>


    </link>

    <link name="base_scan">    
      <inertial>
        <pose>-0.014 0 0.200 0 0 0</pose>
        <inertia>
          <ixx>0.001</ixx>
          <ixy>0.000</ixy>
          <ixz>0.000</ixz>
          <iyy>0.001</iyy>
          <iyz>0.000</iyz>
          <izz>0.001</izz>
        </inertia>
        <mass>0.125</mass>
      </inertial>

      <collision name="lidar_sensor_collision">
        <pose>-0.014 0 0.200 0 0 0</pose>
        <geometry>
          <cylinder>
            <radius>0.0325</radius>
            <length>0.020</length>
          </cylinder>
        </geometry>
      </collision>

      <visual name="lidar_sensor_visual">
        <pose>-0.014 0 0.20 0 0 0</pose>
        <geometry>
            <cylinder>
              <length>0.020</length>
              <radius>0.0325</radius>
            </cylinder>
        </geometry>
        <material>
          <ambient>0.109 0.204 0.518 1</ambient>
          <diffuse>0.121 0.227 0.576 1</diffuse>
        </material>
      </visual>

      <sensor name="ydlidar_x4" type="ray">
        <always_on>true</always_on>
        <visualize>true</visualize>
        <pose>-0.014 0 0.20 0 0 0</pose>
        <!-- 5 Hz rotation -->
        <update_rate>5</update_rate>
        <ray>
          <scan>
            <horizontal>
              <samples>720</samples>
              <resolution>0.5</resolution>
              <min_angle>-3.14159</min_angle>
              <max_angle>3.14159</max_angle>
            </horizontal>
          </scan>
          <range>
            <min>0.120000</min>
            <max>10.0</max>
            <!--2cm out to 0.5m, 1.5% out to 6m = 9cm-->
            <resolution>0.02000</resolution>
          </range>
          <noise>
            <type>gaussian</type>
            <mean>0.0</mean>
            <stddev>0.015</stddev>
          </noise>
        </ray>

        <plugin name="gpg3_laserscan" filename="libgazebo_ros_ray_sensor.so">
          <ros>
            <!-- <namespace>/gpg3</namespace> -->
            <remapping>~/out:=scan</remapping>
          </ros>
          <output_type>sensor_msgs/LaserScan</output_type>
          <frame_name>base_scan</frame_name>
        </plugin>
     </sensor>

    </link>

    <link name="base_image">    
      <inertial>
        <pose>0.08 0 0.162 0 0 0</pose>
        <inertia>
          <ixx>0.001</ixx>
          <ixy>0.000</ixy>
          <ixz>0.000</ixz>
          <iyy>0.001</iyy>
          <iyz>0.000</iyz>
          <izz>0.001</izz>
        </inertia>
        <mass>0.125</mass>
      </inertial>

      <collision name="image_sensor_collision">
        <pose>0.08 0 0.162 0 0 0</pose>
        <geometry>
          <box>
            <size>0.022 0.097 0.030</size>
          </box>
        </geometry>
      </collision>

      <visual name="image_sensor_visual">
        <pose>0.08 0 0.162 0 0 0</pose>
        <geometry>
          <box>
            <size>0.022 0.097 0.030</size>
          </box>
        </geometry>
        <material>
          <ambient>0.01 0.01 0.01 1</ambient>
          <diffuse>0.1 0.1 0.1 1</diffuse>
        </material>
      </visual>

      <sensor name="oak_d_w_rgb" type="camera">
        <always_on>1</always_on>
        <visualize>0</visualize>
        <update_rate>30</update_rate>
        <pose>0.08 0 0.162 0 0 0</pose>
        <camera>
          <horizontal_fov>2.23402</horizontal_fov>
          <image>
            <width>1280</width>
            <height>800</height>
            <format>R8G8B8</format>
          </image>
          <clip>
            <near>0.018</near>
            <far>300</far>
          </clip>
        </camera>
      </sensor>
    </link>

    <link name="wheel_left_link">

      <inertial>
        <pose>0.0 0.058 0.033385 -1.57 0 0</pose>
        <inertia>
          <ixx>0.001</ixx>
          <ixy>0.000</ixy>
          <ixz>0.000</ixz>
          <iyy>0.001</iyy>
          <iyz>0.000</iyz>
          <izz>0.001</izz>
        </inertia>
        <mass>0.1</mass>
      </inertial>

      <collision name="left_wheel_collision">
        <pose>0.0 0.058 0.033385 -1.57 0 0</pose>
        <geometry>
          <cylinder>
            <radius>0.03385</radius>
            <length>0.025</length>
          </cylinder>
        </geometry>
          <surface>
            <friction>
              <ode>
                <mu>100000.0</mu>
                <mu2>100000.0</mu2>
                <fdir1>0 0 0</fdir1>
                <slip1>0.0</slip1>
                <slip2>0.0</slip2>
              </ode>
          </friction>
        </surface>
      </collision>

      <visual name="left_wheel_visual">
        <pose>0.0 0.058 0.033385 -1.57 0 0</pose>
        <geometry>
          <cylinder>
            <length>0.025</length>
            <radius>0.03385</radius>
          </cylinder>
        </geometry>
        <material>
          <ambient>0.9 0 0 1</ambient>
          <diffuse>1 0 0 1</diffuse>
        </material>

      </visual>
    </link>

    <link name="wheel_right_link">

      <inertial>
        <pose>0.0 -0.058 0.033385 -1.57 0 0</pose>
        <inertia>
          <ixx>0.001</ixx>
          <ixy>0.000</ixy>
          <ixz>0.000</ixz>
          <iyy>0.001</iyy>
          <iyz>0.000</iyz>
          <izz>0.001</izz>
        </inertia>
        <mass>0.1</mass>
      </inertial>
    
      <collision name="right_wheel_collision">
        <pose>0.0 -0.058 0.033385 -1.57 0 0</pose>
        <geometry>
          <cylinder>
            <radius>0.03385</radius>
            <length>0.025</length>
          </cylinder>
        </geometry>
          <surface>
            <friction>
              <ode>
                <mu>100000.0</mu>
                <mu2>100000.0</mu2>
                <fdir1>0 0 0</fdir1>
                <slip1>0.0</slip1>
                <slip2>0.0</slip2>
              </ode>
          </friction>
        </surface>
      </collision>

      <visual name="right_wheel_visual">
        <pose>0.0 -0.058 0.033385 -1.57 0 0</pose>
        <geometry>
          <cylinder>
            <length>0.025</length>
            <radius>0.03385</radius>
          </cylinder>
        </geometry>
        <material>
          <ambient>0 0.9 0 1</ambient>
          <diffuse>0 1 0 1</diffuse>
        </material>

      </visual>
    </link>

    <link name="rear_castor_link">

      <inertial>
        <pose>-0.114 0 0.01 0 0 0</pose>
        <inertia>
          <ixx>0.001</ixx>
          <ixy>0.000</ixy>
          <ixz>0.000</ixz>
          <iyy>0.001</iyy>
          <iyz>0.000</iyz>
          <izz>0.001</izz>
        </inertia>
        <mass>0.1</mass>
      </inertial>

      <collision name="rear_caster_collision">
        <pose>-0.114 0 0.01 0 0 0</pose>
        <geometry>
          <sphere>
            <radius>0.01</radius>
          </sphere>
        </geometry>
        <!--  <surface>
            <friction>
              <ode>
                <mu>100000.0</mu>
                <mu2>100000.0</mu2>
                <fdir1>0 0 0</fdir1>
                <slip1>0.0</slip1>
                <slip2>0.0</slip2>
              </ode>
          </friction>
        </surface> -->
      </collision>

      <visual name="rear_caster_visual">
        <pose>-0.114 0 0.01 0 0 0</pose>
        <geometry>
          <sphere>
            <radius>0.01</radius>
          </sphere>
        </geometry>
        <material>
          <ambient>0.9 0.9 0.9 1</ambient>
          <diffuse>1 1 1 1</diffuse>
        </material>
      </visual>

    </link>


    <joint name="wheel_left_joint" type="revolute">
      <parent>base_link</parent>
      <child>wheel_left_link</child>
      <pose>0.0 0.058 0.033385 -1.57 0 0</pose>
     <axis>
        <xyz>0 0 1</xyz>
      </axis>
    </joint>

    <joint name="wheel_right_joint" type="revolute">
      <parent>base_link</parent>
      <child>wheel_right_link</child>
      <pose>0.0 -0.058 0.033385 -1.57 0 0</pose>
      <axis>
        <xyz>0 0 1</xyz>
      </axis>
    </joint>

    <joint name="oak_d_w_joint" type="fixed">
      <parent>base_link</parent>
      <child>base_image</child>
      <pose>0 0 0 0 0 0</pose>
      <axis>
        <xyz>0 0 1</xyz>
      </axis>
    </joint>

    <joint name="lidar_joint" type="fixed">
      <parent>base_link</parent>
      <child>base_scan</child>
      <pose>0 0 0 0 0 0</pose>
      <axis>
        <xyz>0 0 1</xyz>
      </axis>
    </joint>

    <joint name="rear_caster_joint" type="ball">
      <parent>base_link</parent>
      <child>rear_castor_link</child>
    </joint>

    <joint name="base_joint" type="fixed">
       <parent>base_footprint</parent>
       <child>base_link</child>
       <pose>0 0 0  0 0 0</pose>
    </joint>

    <plugin name="gpg3_diff_drive" filename="libgazebo_ros_diff_drive.so">

      <ros>
        <!-- <namespace>/tb3</namespace> -->
      </ros>

      <update_rate>30</update_rate>

      <!-- wheels -->
      <left_joint>wheel_left_joint</left_joint>
      <right_joint>wheel_right_joint</right_joint>

      <!-- kinematics for GoPi5Go-Dave -->
      <wheel_separation>0.10509</wheel_separation>
      <wheel_diameter>0.06605</wheel_diameter>

      <!-- limits -->
      <max_wheel_torque>20</max_wheel_torque>
      <max_wheel_acceleration>1.0</max_wheel_acceleration>

      <command_topic>cmd_vel</command_topic>

      <!-- output -->
      <publish_odom>true</publish_odom>
      <publish_odom_tf>true</publish_odom_tf>
      <publish_wheel_tf>false</publish_wheel_tf>

      <odometry_topic>odom</odometry_topic>
      <odometry_frame>odom</odometry_frame>
      <robot_base_frame>base_footprint</robot_base_frame>

    </plugin>

    <plugin name="gpg3_joint_state" filename="libgazebo_ros_joint_state_publisher.so">
      <ros>
        <!-- <namespace>/tb3</namespace> -->
        <remapping>~/out:=joint_states</remapping>
      </ros>
      <update_rate>30</update_rate>
      <joint_name>wheel_left_joint</joint_name>
      <joint_name>wheel_right_joint</joint_name>
    </plugin>    



  </model>
</sdf>
